<?xml version="1.0" ?>
<robot name="vine_robot">
    <!-- MATERIALS -->
    <material name="white">
        <color rgba="1.0 1.0 1.0 1.0"/>
    </material>
    <material name="black">
        <color rgba="0.0 0.0 0.0 1.0"/>
    </material>
    <material name="red">
        <color rgba="1.0 0.0 0.0 1.0"/>
    </material>
    <material name="green">
        <color rgba="0.0 1.0 0.0 0.0"/>
    </material>
    <material name="blue">
        <color rgba="0.0 0.0 1.0 0.0"/>
    </material>
    <material name="magenta">
        <color rgba="1.0 0.0 1.0 0.0"/>
    </material>
    <material name="teal">
        <color rgba="0.0 1.0 1.0 0.0"/>
    </material>
    <material name="yellow">
        <color rgba="1.0 1.0 0.0 0.0"/>
    </material>

    <!-- LINKS -->
    <!-- Alternate between links with mass and virtual links to connect joints -->
    <!-- Inertial tags need fixing -->
    <!-- Decide on best shape for links -->
    <link name="base_link">
        <inertial>
            <mass value="1"/>
            <inertia ixx="1" ixy="0" ixz="0" iyy="1" iyz="0" izz="1"/>
        </inertial>

        <collision>
            <geometry>
                <cylinder radius="0.025" length="0.1"/>
            </geometry>
            <origin xyz="0 0 0" rpy="0 1.57 0"/>
        </collision>

        <visual>
            <geometry>
                <cylinder radius="0.025" length="0.1"/>
            </geometry>
            <origin xyz="0 0 0" rpy="0 1.57 0"/>
            <material name="red"/>
        </visual>

    </link>

    <link name="base_virtual_link"/>

    <link name="link_0_0">
        <inertial>
            <mass value="0.1"/>
            <inertia ixx="0.1" ixy="0" ixz="0" iyy="0.1" iyz="0" izz="0.1"/>
        </inertial>

        <collision>
            <geometry>
                <cylinder radius="0.025" length="0.1"/>
            </geometry>
            <origin xyz="0 0 0" rpy="0 1.57 0"/>
        </collision>

        <visual>
            <geometry>
                <cylinder radius="0.025" length="0.1"/>
            </geometry>
            <origin xyz="0 0 0" rpy="0 1.57 0"/>
            <material name="red"/>
        </visual>
    </link>

    <link name="link_0_1">
        <inertial>
            <mass value="0.01"/>
            <inertia ixx="0.01" ixy="0" ixz="0" iyy="0.01" iyz="0" izz="0.01"/>
        </inertial>

        <collision>
            <geometry>
                <cylinder radius="0.025" length="0.1"/>
            </geometry>
            <origin xyz="0 0 0" rpy="0 1.57 0"/>
        </collision>

        <visual>
            <geometry>
                <cylinder radius="0.025" length="0.1"/>
            </geometry>
            <origin xyz="0 0 0" rpy="0 1.57 0"/>
            <material name="red"/>
        </visual>
    </link>

    <link name="link_0_2">
        <inertial>
            <mass value="0.001"/>
            <inertia ixx="0.001" ixy="0" ixz="0" iyy="0.001" iyz="0" izz="0.001"/>
        </inertial>

        <collision>
            <geometry>
                <cylinder radius="0.025" length="0.1"/>
            </geometry>
            <origin xyz="0 0 0" rpy="0 1.57 0"/>
        </collision>

        <visual>
            <geometry>
                <cylinder radius="0.025" length="0.1"/>
            </geometry>
            <origin xyz="0 0 0" rpy="0 1.57 0"/>
            <material name="red"/>
        </visual>
    </link>

    <link name="virtual_link_0"/>

    <link name="link_1_0">
        <inertial>
            <mass value="0.1"/>
            <inertia ixx="0.1" ixy="0" ixz="0" iyy="0.1" iyz="0" izz="0.1"/>
        </inertial>

        <collision>
            <geometry>
                <cylinder radius="0.025" length="0.1"/>
            </geometry>
            <origin xyz="0 0 0" rpy="0 1.57 0"/>
        </collision>

        <visual>
            <geometry>
                <cylinder radius="0.025" length="0.1"/>
            </geometry>
            <origin xyz="0 0 0" rpy="0 1.57 0"/>
            <material name="red"/>
        </visual>
    </link>

    <link name="link_1_1">
        <inertial>
            <mass value="0.01"/>
            <inertia ixx="0.01" ixy="0" ixz="0" iyy="0.01" iyz="0" izz="0.01"/>
        </inertial>

        <collision>
            <geometry>
                <cylinder radius="0.025" length="0.1"/>
            </geometry>
            <origin xyz="0 0 0" rpy="0 1.57 0"/>
        </collision>

        <visual>
            <geometry>
                <cylinder radius="0.025" length="0.1"/>
            </geometry>
            <origin xyz="0 0 0" rpy="0 1.57 0"/>
            <material name="red"/>
        </visual>
    </link>

    <link name="link_1_2">
        <inertial>
            <mass value="0.001"/>
            <inertia ixx="0.001" ixy="0" ixz="0" iyy="0.001" iyz="0" izz="0.001"/>
        </inertial>

        <collision>
            <geometry>
                <cylinder radius="0.025" length="0.1"/>
            </geometry>
            <origin xyz="0 0 0" rpy="0 1.57 0"/>
        </collision>

        <visual>
            <geometry>
                <cylinder radius="0.025" length="0.1"/>
            </geometry>
            <origin xyz="0 0 0" rpy="0 1.57 0"/>
            <material name="red"/>
        </visual>
    </link>

    <link name="virtual_link_1"/>



    <link name="link_2_0">
        <inertial>
            <mass value="0.1"/>
            <inertia ixx="0.1" ixy="0" ixz="0" iyy="0.1" iyz="0" izz="0.1"/>
        </inertial>

        <collision>
            <geometry>
                <cylinder radius="0.025" length="0.1"/>
            </geometry>
            <origin xyz="0 0 0" rpy="0 1.57 0"/>
        </collision>

        <visual>
            <geometry>
                <cylinder radius="0.025" length="0.1"/>
            </geometry>
            <origin xyz="0 0 0" rpy="0 1.57 0"/>
            <material name="red"/>
        </visual>
    </link>

    <link name="link_2_1">
        <inertial>
            <mass value="0.01"/>
            <inertia ixx="0.01" ixy="0" ixz="0" iyy="0.01" iyz="0" izz="0.01"/>
        </inertial>

        <collision>
            <geometry>
                <cylinder radius="0.025" length="0.1"/>
            </geometry>
            <origin xyz="0 0 0" rpy="0 1.57 0"/>
        </collision>

        <visual>
            <geometry>
                <cylinder radius="0.025" length="0.1"/>
            </geometry>
            <origin xyz="0 0 0" rpy="0 1.57 0"/>
            <material name="red"/>
        </visual>
    </link>

    <link name="link_2_2">
        <inertial>
            <mass value="0.001"/>
            <inertia ixx="0.001" ixy="0" ixz="0" iyy="0.001" iyz="0" izz="0.001"/>
        </inertial>

        <collision>
            <geometry>
                <cylinder radius="0.025" length="0.1"/>
            </geometry>
            <origin xyz="0 0 0" rpy="0 1.57 0"/>
        </collision>

        <visual>
            <geometry>
                <cylinder radius="0.025" length="0.1"/>
            </geometry>
            <origin xyz="0 0 0" rpy="0 1.57 0"/>
            <material name="red"/>
        </visual>
    </link>

    <!-- JOINTS -->
    <!-- Alternate between 1 revolute joint (link to virtual link) and 3 prismatic joints -->
    <!-- Segment lengths usually at most 1 meters, so use 0.5m (prismatic upper limit)-->
    <!-- Joint angles usually at most [-30, 30] degrees => [-0.5236, 0.5236] radians (revolute limits)-->
    <!-- Max growth speed is about 0.1m/s (prismatic joint velocity limit) -->
    <!-- Other efforts and velocities currently untuned -->
    <joint name="revolute_joint_0" type="revolute">
        <!-- Maybe should be rotation/continuous -->
        <origin xyz="0.0 0.0 0.0" rpy="0.0 0.0 0.0"/>
        <parent link="base_link"/>
        <child link="base_virtual_link"/>
        <axis xyz="0.0 0.0 1.0"/>
        <!-- <limit lower="-3.146" upper="3.146" effort="10000" velocity="3"/> -->
        <limit lower="-0.5236" upper="0.5236" effort="10000" velocity="3"/>
    </joint>
    <joint name="prismatic_joint_0_0" type="prismatic">
        <origin xyz="0.0 0.0 0.0" rpy="0.0 0.0 0.0"/>
        <parent link="base_virtual_link"/>
        <child link="link_0_0"/>
        <axis xyz="1.0 0.0 0.0"/>
        <limit lower="0.0" upper="0.1" effort="10000" velocity="1"/>
    </joint>
    <joint name="prismatic_joint_0_1" type="prismatic">
        <origin xyz="0.0 0.0 0.0" rpy="0.0 0.0 0.0"/>
        <parent link="link_0_0"/>
        <child link="link_0_1"/>
        <axis xyz="1.0 0.0 0.0"/>
        <limit lower="0.0" upper="0.1" effort="10000" velocity="1"/>
    </joint>
    <joint name="prismatic_joint_0_2" type="prismatic">
        <origin xyz="0.0 0.0 0.0" rpy="0.0 0.0 0.0"/>
        <parent link="link_0_1"/>
        <child link="link_0_2"/>
        <axis xyz="1.0 0.0 0.0"/>
        <limit lower="0.0" upper="0.1" effort="10000" velocity="1"/>
    </joint>
    <joint name="revolute_joint_1" type="revolute">
        <origin xyz="0.0 0.0 0.0" rpy="0.0 0.0 0.0"/>
        <parent link="link_0_2"/>
        <child link="virtual_link_0"/>
        <axis xyz="0.0 0.0 1.0"/>
        <limit lower="-0.5236" upper="0.5236" effort="10000" velocity="3"/>
    </joint>
    <joint name="prismatic_joint_1_0" type="prismatic">
        <origin xyz="0.0 0.0 0.0" rpy="0.0 0.0 0.0"/>
        <parent link="virtual_link_0"/>
        <child link="link_1_0"/>
        <axis xyz="1.0 0.0 0.0"/>
        <limit lower="0.0" upper="0.1" effort="10000" velocity="1"/>
    </joint>
    <joint name="prismatic_joint_1_1" type="prismatic">
        <origin xyz="0.0 0.0 0.0" rpy="0.0 0.0 0.0"/>
        <parent link="link_1_0"/>
        <child link="link_1_1"/>
        <axis xyz="1.0 0.0 0.0"/>
        <limit lower="0.0" upper="0.1" effort="10000" velocity="1"/>
    </joint>
    <joint name="prismatic_joint_1_2" type="prismatic">
        <origin xyz="0.0 0.0 0.0" rpy="0.0 0.0 0.0"/>
        <parent link="link_1_1"/>
        <child link="link_1_2"/>
        <axis xyz="1.0 0.0 0.0"/>
        <limit lower="0.0" upper="0.1" effort="10000" velocity="1"/>
    </joint>


    <joint name="revolute_joint_2" type="revolute">
        <origin xyz="0.0 0.0 0.0" rpy="0.0 0.0 0.0"/>
        <parent link="link_1_2"/>
        <child link="virtual_link_1"/>
        <axis xyz="0.0 0.0 1.0"/>
        <limit lower="-0.5236" upper="0.5236" effort="10000" velocity="3"/>
    </joint>
    <joint name="prismatic_joint_2_0" type="prismatic">
        <origin xyz="0.0 0.0 0.0" rpy="0.0 0.0 0.0"/>
        <parent link="virtual_link_1"/>
        <child link="link_2_0"/>
        <axis xyz="1.0 0.0 0.0"/>
        <limit lower="0.0" upper="0.1" effort="10000" velocity="1"/>
    </joint>
    <joint name="prismatic_joint_2_1" type="prismatic">
        <origin xyz="0.0 0.0 0.0" rpy="0.0 0.0 0.0"/>
        <parent link="link_2_0"/>
        <child link="link_2_1"/>
        <axis xyz="1.0 0.0 0.0"/>
        <limit lower="0.0" upper="0.1" effort="10000" velocity="1"/>
    </joint>
    <joint name="prismatic_joint_2_2" type="prismatic">
        <origin xyz="0.0 0.0 0.0" rpy="0.0 0.0 0.0"/>
        <parent link="link_2_1"/>
        <child link="link_2_2"/>
        <axis xyz="1.0 0.0 0.0"/>
        <limit lower="0.0" upper="0.1" effort="10000" velocity="1"/>
    </joint>

</robot>
