<?xml version="1.0"?>
<robot name="vine_robot">
    <!-- MATERIALS -->
    <material name="white">
        <color rgba="1.0 1.0 1.0 1.0" />
    </material>
    <material name="black">
        <color rgba="0.0 0.0 0.0 1.0" />
    </material>
    <material name="red">
        <color rgba="1.0 0.0 0.0 1.0" />
    </material>
    <material name="green">
        <color rgba="0.0 1.0 0.0 0.0" />
    </material>
    <material name="blue">
        <color rgba="0.0 0.0 1.0 0.0" />
    </material>
    <material name="magenta">
        <color rgba="1.0 0.0 1.0 0.0" />
    </material>
    <material name="teal">
        <color rgba="0.0 1.0 1.0 0.0" />
    </material>
    <material name="yellow">
        <color rgba="1.0 1.0 0.0 0.0" />
    </material>
    <material name="iron">
        <color rgba="0.56 0.57 0.58 0.0" />
    </material>

    <!-- LINKS -->
    <!-- 1 slider link, 1 cart link, and 5 cylindrical links -->

    <!-- SLIDER -->
    <!-- length=0.8m (technically 1m, but round down to be safe) -->
    <!-- arbitrary other dims = 0.03 -->
    <!-- assume no mass, will be fixed base -->
    <link name="slider">
        <visual>
            <geometry>
                <box size="0.03 0.8 0.03" />
            </geometry>
            <material name="iron" />
        </visual>
        <collision>
            <geometry>
                <box size="0.03 8 0.03" />
            </geometry>
        </collision>
    </link>

    <!-- CART -->
    <!-- dimensions = 7cm x 10cm x 2cm (length parallel to rail is 10cm) -->
    <!-- mass ~= 0.4kg -->
    <link name="cart">
        <visual>
            <geometry>
                <box size="0.07 0.1 0.02" />
            </geometry>
            <material name="black" />
        </visual>
        <collision>
            <geometry>
                <box size="0.07 0.1 0.02" />
            </geometry>
        </collision>
        <inertial>
            <mass value="0.4" />
        </inertial>
    </link>

    <!-- CYLINDERS -->
    <!-- Each link has radius = 0.0381 m  length = 0.0885 m -->
    <!-- First 4 are "shells" with mass 0.005 -->
    <!--                      with inertia ixx = 6.89246e-6, iyy = 6.89246e-6, izz = 7.25805e-6 (others 0)-->
    <!-- Last 1 is full cylinder with mass 0.1 -->
    <!--                         with inertia ixx = 0.000101559, iyy = 0.000101559, izz = 7.25805e-5 (others 0)-->
    <link name="link_0">
        <inertial>
            <origin xyz="0.0 0.0 0.04425" rpy="0.0 0.0 0.0" />
            <mass value="0.005" />
            <inertia ixx="0.00000689246" ixy="0.0" ixz="0.0" iyy="0.00000689246" iyz="0.0" izz="0.00000725805" />
        </inertial>
        <visual>
            <origin xyz="0.0 0.0 0.04425" rpy="0.0 0.0 0.0" />
            <geometry>
                <cylinder radius="0.0381" length="0.0885" />
            </geometry>
            <material name="blue" />
        </visual>
        <collision>
            <origin xyz="0.0 0.0 0.04425" rpy="0.0 0.0 0.0" />
            <geometry>
                <cylinder radius="0.0381" length="0.0885" />
            </geometry>
        </collision>
    </link>
    <link name="link_1">
        <inertial>
            <origin xyz="0.0 0.0 0.04425" rpy="0.0 0.0 0.0" />
            <mass value="0.005" />
            <inertia ixx="0.00000689246" ixy="0.0" ixz="0.0" iyy="0.00000689246" iyz="0.0" izz="0.00000725805" />
        </inertial>
        <visual>
            <origin xyz="0.0 0.0 0.04425" rpy="0.0 0.0 0.0" />
            <geometry>
                <cylinder radius="0.0381" length="0.0885" />
            </geometry>
            <material name="blue" />
        </visual>
        <collision>
            <origin xyz="0.0 0.0 0.04425" rpy="0.0 0.0 0.0" />
            <geometry>
                <cylinder radius="0.0381" length="0.0885" />
            </geometry>
        </collision>
    </link>
    <link name="link_2">
        <inertial>
            <origin xyz="0.0 0.0 0.04425" rpy="0.0 0.0 0.0" />
            <mass value="0.005" />
            <inertia ixx="0.00000689246" ixy="0.0" ixz="0.0" iyy="0.00000689246" iyz="0.0" izz="0.00000725805" />
        </inertial>
        <visual>
            <origin xyz="0.0 0.0 0.04425" rpy="0.0 0.0 0.0" />
            <geometry>
                <cylinder radius="0.0381" length="0.0885" />
            </geometry>
            <material name="blue" />
        </visual>
        <collision>
            <origin xyz="0.0 0.0 0.04425" rpy="0.0 0.0 0.0" />
            <geometry>
                <cylinder radius="0.0381" length="0.0885" />
            </geometry>
        </collision>
    </link>
    <link name="link_3">
        <inertial>
            <origin xyz="0.0 0.0 0.04425" rpy="0.0 0.0 0.0" />
            <mass value="0.005" />
            <inertia ixx="0.00000689246" ixy="0.0" ixz="0.0" iyy="0.00000689246" iyz="0.0" izz="0.00000725805" />
        </inertial>
        <visual>
            <origin xyz="0.0 0.0 0.04425" rpy="0.0 0.0 0.0" />
            <geometry>
                <cylinder radius="0.0381" length="0.0885" />
            </geometry>
            <material name="blue" />
        </visual>
        <collision>
            <origin xyz="0.0 0.0 0.04425" rpy="0.0 0.0 0.0" />
            <geometry>
                <cylinder radius="0.0381" length="0.0885" />
            </geometry>
        </collision>
    </link>
    <link name="link_4">
        <inertial>
            <origin xyz="0.0 0.0 0.04425" rpy="0.0 0.0 0.0" />
            <mass value="0.1" />
            <inertia ixx="0.000101559" ixy="0.0" ixz="0.0" iyy="0.000101559" iyz="0.0" izz="0.0000725805" />
        </inertial>
        <visual>
            <origin xyz="0.0 0.0 0.04425" rpy="0.0 0.0 0.0" />
            <geometry>
                <cylinder radius="0.0381" length="0.0885" />
            </geometry>
            <material name="blue" />
        </visual>
        <collision>
            <origin xyz="0.0 0.0 0.04425" rpy="0.0 0.0 0.0" />
            <geometry>
                <cylinder radius="0.0381" length="0.0885" />
            </geometry>
        </collision>
    </link>
    <link name="tip"/>
    <!-- Visual limits -->
    <link name="left_limit">
        <visual>
            <origin xyz="0.0 0.0 0.0" rpy="0.0 0.0 0.0" />
            <geometry>
                <box size="0.03 0.03 0.2" />
            </geometry>
            <material name="red" />
        </visual>
    </link>
    <link name="right_limit">
        <visual>
            <origin xyz="0.0 0.0 0.0" rpy="0.0 0.0 0.0" />
            <geometry>
                <box size="0.03 0.03 0.2" />
            </geometry>
            <material name="red" />
        </visual>
    </link>

    <!-- JOINTS -->
    <!-- 1 slider joint, 5 revolute joints -->

    <!-- PRISMATIC -->
    <!-- conservative values: effort=1N, velocity=0.5m/s  -->
    <!-- length=0.8m (technically 1m, but round down to be safe), so limits are halfway in each dir, minus cart size -->
    <joint name="slider_to_cart" type="prismatic">
        <axis xyz="0.0 1.0 0.0" />

        <!-- Change z to set relative position of cart wrt slider (half rail and half cart height) -->
        <origin xyz="0.0 0.0 -0.025" rpy="0.0 0.0 0.0" />

        <parent link="slider" />
        <child link="cart" />
        <!-- <limit lower="-0.35" upper="0.35" effort="1" velocity="0.5" /> -->
    </joint>

    <!-- REVOLUTE -->
    <!-- Do not need to enforce limits because the model SHOULD handle it, in fact adding 30 deg limit caused some instabilities -->
    <joint name="cart_to_link_0" type="revolute">
        <axis xyz="1.0 0.0 0.0" />

        <!-- Change z to set relative position of link wrt cart (half cart height) -->
        <origin xyz="0.0 0.0 -0.01" rpy="3.1415 0.0 0.0" />

        <parent link="cart" />
        <child link="link_0" />
        <!-- <limit lower="-0.523599" upper="0.523599" /> -->
    </joint>
    <joint name="link_0_to_link_1" type="revolute">
        <axis xyz="1.0 0.0 0.0" />
        <origin xyz="0.0 0.0 0.0885" rpy="0.0 0.0 0.0" />
        <parent link="link_0" />
        <child link="link_1" />
        <!-- <limit lower="-0.523599" upper="0.523599" /> -->
    </joint>
    <joint name="link_1_to_link_2" type="revolute">
        <axis xyz="1.0 0.0 0.0" />
        <origin xyz="0.0 0.0 0.0885" rpy="0.0 0.0 0.0" />
        <parent link="link_1" />
        <child link="link_2" />
        <!-- <limit lower="-0.523599" upper="0.523599" /> -->
    </joint>
    <joint name="link_2_to_link_3" type="revolute">
        <axis xyz="1.0 0.0 0.0" />
        <origin xyz="0.0 0.0 0.0885" rpy="0.0 0.0 0.0" />
        <parent link="link_2" />
        <child link="link_3" />
        <!-- <limit lower="-0.523599" upper="0.523599" /> -->
    </joint>
    <joint name="link_3_to_link_4" type="revolute">
        <axis xyz="1.0 0.0 0.0" />
        <origin xyz="0.0 0.0 0.0885" rpy="0.0 0.0 0.0" />
        <parent link="link_3" />
        <child link="link_4" />
        <!-- <limit lower="-0.523599" upper="0.523599" /> -->
    </joint>
    <joint name="link_4_to_tip" type="fixed">
        <origin xyz="0.0 0.0 0.0885" rpy="0.0 0.0 0.0" />
        <parent link="link_4" />
        <child link="tip" />
    </joint>

    <!-- Brittleness warning: Need to modify this position based on code -->
    <joint name="slider_to_left_limit" type="fixed">
        <origin xyz="0.0 -0.3 0.0" rpy="0.0 0.0 0.0" />
        <parent link="slider" />
        <child link="left_limit" />
    </joint>
    <joint name="slider_to_right_limit" type="fixed">
        <origin xyz="0.0 0.3 0.0" rpy="0.0 0.0 0.0" />
        <parent link="slider" />
        <child link="right_limit" />
    </joint>
</robot>
